Compiled from "PromiseNotificationUtil.java"
public final class io.netty.util.internal.PromiseNotificationUtil {
  private io.netty.util.internal.PromiseNotificationUtil();
    Code:
       0: aload_0
       1: invokespecial #9                  // Method java/lang/Object."<init>":()V
       4: return

  public static void tryCancel(io.netty.util.concurrent.Promise<?>, io.netty.util.internal.logging.InternalLogger);
    Code:
       0: aload_0
       1: iconst_0
       2: invokeinterface #20,  2           // InterfaceMethod io/netty/util/concurrent/Promise.cancel:(Z)Z
       7: ifne          47
      10: aload_1
      11: ifnull        47
      14: aload_0
      15: invokeinterface #24,  1           // InterfaceMethod io/netty/util/concurrent/Promise.cause:()Ljava/lang/Throwable;
      20: astore_2
      21: aload_2
      22: ifnonnull     37
      25: aload_1
      26: ldc           #26                 // String Failed to cancel promise because it has succeeded already: {}
      28: aload_0
      29: invokeinterface #32,  3           // InterfaceMethod io/netty/util/internal/logging/InternalLogger.warn:(Ljava/lang/String;Ljava/lang/Object;)V
      34: goto          47
      37: aload_1
      38: ldc           #36                 // String Failed to cancel promise because it has failed already: {}, unnotified cause:
      40: aload_0
      41: aload_2
      42: invokeinterface #39,  4           // InterfaceMethod io/netty/util/internal/logging/InternalLogger.warn:(Ljava/lang/String;Ljava/lang/Object;Ljava/lang/Object;)V
      47: return

  public static <V> void trySuccess(io.netty.util.concurrent.Promise<? super V>, V, io.netty.util.internal.logging.InternalLogger);
    Code:
       0: aload_0
       1: aload_1
       2: invokeinterface #52,  2           // InterfaceMethod io/netty/util/concurrent/Promise.trySuccess:(Ljava/lang/Object;)Z
       7: ifne          47
      10: aload_2
      11: ifnull        47
      14: aload_0
      15: invokeinterface #24,  1           // InterfaceMethod io/netty/util/concurrent/Promise.cause:()Ljava/lang/Throwable;
      20: astore_3
      21: aload_3
      22: ifnonnull     37
      25: aload_2
      26: ldc           #54                 // String Failed to mark a promise as success because it has succeeded already: {}
      28: aload_0
      29: invokeinterface #32,  3           // InterfaceMethod io/netty/util/internal/logging/InternalLogger.warn:(Ljava/lang/String;Ljava/lang/Object;)V
      34: goto          47
      37: aload_2
      38: ldc           #56                 // String Failed to mark a promise as success because it has failed already: {}, unnotified cause:
      40: aload_0
      41: aload_3
      42: invokeinterface #39,  4           // InterfaceMethod io/netty/util/internal/logging/InternalLogger.warn:(Ljava/lang/String;Ljava/lang/Object;Ljava/lang/Object;)V
      47: return

  public static void tryFailure(io.netty.util.concurrent.Promise<?>, java.lang.Throwable, io.netty.util.internal.logging.InternalLogger);
    Code:
       0: aload_0
       1: aload_1
       2: invokeinterface #66,  2           // InterfaceMethod io/netty/util/concurrent/Promise.tryFailure:(Ljava/lang/Throwable;)Z
       7: ifne          74
      10: aload_2
      11: ifnull        74
      14: aload_0
      15: invokeinterface #24,  1           // InterfaceMethod io/netty/util/concurrent/Promise.cause:()Ljava/lang/Throwable;
      20: astore_3
      21: aload_3
      22: ifnonnull     38
      25: aload_2
      26: ldc           #68                 // String Failed to mark a promise as failure because it has succeeded already: {}
      28: aload_0
      29: aload_1
      30: invokeinterface #39,  4           // InterfaceMethod io/netty/util/internal/logging/InternalLogger.warn:(Ljava/lang/String;Ljava/lang/Object;Ljava/lang/Object;)V
      35: goto          74
      38: aload_2
      39: invokeinterface #72,  1           // InterfaceMethod io/netty/util/internal/logging/InternalLogger.isWarnEnabled:()Z
      44: ifeq          74
      47: aload_2
      48: ldc           #74                 // String Failed to mark a promise as failure because it has failed already: {}, unnotified cause: {}
      50: iconst_3
      51: anewarray     #4                  // class java/lang/Object
      54: dup
      55: iconst_0
      56: aload_0
      57: aastore
      58: dup
      59: iconst_1
      60: aload_3
      61: invokestatic  #80                 // Method io/netty/util/internal/ThrowableUtil.stackTraceToString:(Ljava/lang/Throwable;)Ljava/lang/String;
      64: aastore
      65: dup
      66: iconst_2
      67: aload_1
      68: aastore
      69: invokeinterface #83,  3           // InterfaceMethod io/netty/util/internal/logging/InternalLogger.warn:(Ljava/lang/String;[Ljava/lang/Object;)V
      74: return
}
