Compiled from "Exception.scala"
public final class scala.util.control.Exception$Catch$$anonfun$toTry$1 extends scala.runtime.AbstractFunction1<java.lang.Throwable, scala.util.Failure<scala.runtime.Nothing$>> implements scala.Serializable {
  public static final long serialVersionUID;

  public final scala.util.Failure<scala.runtime.Nothing$> apply(java.lang.Throwable);
    Code:
       0: new           #21                 // class scala/util/Failure
       3: dup
       4: aload_1
       5: invokespecial #25                 // Method scala/util/Failure."<init>":(Ljava/lang/Throwable;)V
       8: areturn

  public final java.lang.Object apply(java.lang.Object);
    Code:
       0: aload_0
       1: aload_1
       2: checkcast     #32                 // class java/lang/Throwable
       5: invokevirtual #34                 // Method apply:(Ljava/lang/Throwable;)Lscala/util/Failure;
       8: areturn

  public scala.util.control.Exception$Catch$$anonfun$toTry$1(scala.util.control.Exception$Catch<T>);
    Code:
       0: aload_0
       1: invokespecial #40                 // Method scala/runtime/AbstractFunction1."<init>":()V
       4: return
}
